Workbook

Sheet Test Execution Summary
A1: Cloudnaut Support Desk — Test Execution Summary
A2: Metrics auto-update from the 'Master Test Cases' sheet.
A4: Metric | B4: Value
A5: Total Test Cases | B5: =COUNTA('Master Test Cases'!$A$5:$A$110)
A6: Not Run | B6: =COUNTIF('Master Test Cases'!$Q$5:$Q$110,"Not Run")
A7: Pass | B7: =COUNTIF('Master Test Cases'!$Q$5:$Q$110,"Pass")
A8: Fail | B8: =COUNTIF('Master Test Cases'!$Q$5:$Q$110,"Fail")
A9: Blocked | B9: =COUNTIF('Master Test Cases'!$Q$5:$Q$110,"Blocked")
A10: Not Applicable | B10: =COUNTIF('Master Test Cases'!$Q$5:$Q$110,"Not Applicable")
A11: Executed (Pass+Fail) | B11: =COUNTIF('Master Test Cases'!$Q$5:$Q$110,"Pass")+COUNTIF('Master Test Cases'!$Q$5:$Q$110,"Fail")
A12: Pass % | B12: =IFERROR(COUNTIF('Master Test Cases'!$Q$5:$Q$110,"Pass")/(COUNTIF('Master Test Cases'!$Q$5:$Q$110,"Pass")+COUNTIF('Master Test Cases'!$Q$5:$Q$110,"Fail")),0)
A13: Execution Progress % | B13: =IFERROR((B5-B6)/B5,0)
A15: Test Cases by Module
A16: Module | B16: Total | C16: Pass | D16: Fail
A17: Access Requests | B17: =COUNTIF('Master Test Cases'!$B$5:$B$110,A17) | C17: =COUNTIFS('Master Test Cases'!$B$5:$B$110,A17,'Master Test Cases'!$Q$5:$Q$110,"Pass") | D17: =COUNTIFS('Master Test Cases'!$B$5:$B$110,A17,'Master Test Cases'!$Q$5:$Q$110,"Fail")
A18: Attachments | B18: =COUNTIF('Master Test Cases'!$B$5:$B$110,A18) | C18: =COUNTIFS('Master Test Cases'!$B$5:$B$110,A18,'Master Test Cases'!$Q$5:$Q$110,"Pass") | D18: =COUNTIFS('Master Test Cases'!$B$5:$B$110,A18,'Master Test Cases'!$Q$5:$Q$110,"Fail")
A19: Authentication | B19: =COUNTIF('Master Test Cases'!$B$5:$B$110,A19) | C19: =COUNTIFS('Master Test Cases'!$B$5:$B$110,A19,'Master Test Cases'!$Q$5:$Q$110,"Pass") | D19: =COUNTIFS('Master Test Cases'!$B$5:$B$110,A19,'Master Test Cases'!$Q$5:$Q$110,"Fail")
A20: Authorization | B20: =COUNTIF('Master Test Cases'!$B$5:$B$110,A20) | C20: =COUNTIFS('Master Test Cases'!$B$5:$B$110,A20,'Master Test Cases'!$Q$5:$Q$110,"Pass") | D20: =COUNTIFS('Master Test Cases'!$B$5:$B$110,A20,'Master Test Cases'!$Q$5:$Q$110,"Fail")
A21: Database | B21: =COUNTIF('Master Test Cases'!$B$5:$B$110,A21) | C21: =COUNTIFS('Master Test Cases'!$B$5:$B$110,A21,'Master Test Cases'!$Q$5:$Q$110,"Pass") | D21: =COUNTIFS('Master Test Cases'!$B$5:$B$110,A21,'Master Test Cases'!$Q$5:$Q$110,"Fail")
A22: End-to-End | B22: =COUNTIF('Master Test Cases'!$B$5:$B$110,A22) | C22: =COUNTIFS('Master Test Cases'!$B$5:$B$110,A22,'Master Test Cases'!$Q$5:$Q$110,"Pass") | D22: =COUNTIFS('Master Test Cases'!$B$5:$B$110,A22,'Master Test Cases'!$Q$5:$Q$110,"Fail")
A23: Frontend | B23: =COUNTIF('Master Test Cases'!$B$5:$B$110,A23) | C23: =COUNTIFS('Master Test Cases'!$B$5:$B$110,A23,'Master Test Cases'!$Q$5:$Q$110,"Pass") | D23: =COUNTIFS('Master Test Cases'!$B$5:$B$110,A23,'Master Test Cases'!$Q$5:$Q$110,"Fail")
A24: Infrastructure | B24: =COUNTIF('Master Test Cases'!$B$5:$B$110,A24) | C24: =COUNTIFS('Master Test Cases'!$B$5:$B$110,A24,'Master Test Cases'!$Q$5:$Q$110,"Pass") | D24: =COUNTIFS('Master Test Cases'!$B$5:$B$110,A24,'Master Test Cases'!$Q$5:$Q$110,"Fail")
A25: Integration | B25: =COUNTIF('Master Test Cases'!$B$5:$B$110,A25) | C25: =COUNTIFS('Master Test Cases'!$B$5:$B$110,A25,'Master Test Cases'!$Q$5:$Q$110,"Pass") | D25: =COUNTIFS('Master Test Cases'!$B$5:$B$110,A25,'Master Test Cases'!$Q$5:$Q$110,"Fail")
A26: Live Chat | B26: =COUNTIF('Master Test Cases'!$B$5:$B$110,A26) | C26: =COUNTIFS('Master Test Cases'!$B$5:$B$110,A26,'Master Test Cases'!$Q$5:$Q$110,"Pass") | D26: =COUNTIFS('Master Test Cases'!$B$5:$B$110,A26,'Master Test Cases'!$Q$5:$Q$110,"Fail")
A27: Request Lifecycle | B27: =COUNTIF('Master Test Cases'!$B$5:$B$110,A27) | C27: =COUNTIFS('Master Test Cases'!$B$5:$B$110,A27,'Master Test Cases'!$Q$5:$Q$110,"Pass") | D27: =COUNTIFS('Master Test Cases'!$B$5:$B$110,A27,'Master Test Cases'!$Q$5:$Q$110,"Fail")
A28: Team Management | B28: =COUNTIF('Master Test Cases'!$B$5:$B$110,A28) | C28: =COUNTIFS('Master Test Cases'!$B$5:$B$110,A28,'Master Test Cases'!$Q$5:$Q$110,"Pass") | D28: =COUNTIFS('Master Test Cases'!$B$5:$B$110,A28,'Master Test Cases'!$Q$5:$Q$110,"Fail")
A30: Test Cases by Priority
A31: Priority | B31: Count
A32: P0 | B32: =COUNTIF('Master Test Cases'!$N$5:$N$110,A32)
A33: P1 | B33: =COUNTIF('Master Test Cases'!$N$5:$N$110,A33)
A34: P2 | B34: =COUNTIF('Master Test Cases'!$N$5:$N$110,A34)
A35: P3 | B35: =COUNTIF('Master Test Cases'!$N$5:$N$110,A35)

Sheet Master Test Cases
A1: Master Test Cases
A2: One row per test case. Leave Actual Result / HTTP Actual / Execution Status until the test is genuinely executed. Status defaults to 'Not Run'.
A4: Test Case ID | B4: Module | C4: Feature | D4: API / Endpoint | E4: Test Scenario | F4: Test Case Description | G4: Preconditions | H4: Test Data | I4: Execution Steps | J4: Expected Result | K4: Actual Result | L4: HTTP Status Code Expected | M4: HTTP Status Code Actual | N4: Priority (P0/P1/P2/P3) | O4: Test Type | P4: Test Level | Q4: Execution Status | R4: Defect ID | S4: Evidence / Screenshot / Log | T4: Automation Status | U4: Source File / Function | V4: Remarks
A5: AUTH-TC-001 | B5: Authentication | C5: Login | D5: POST /auth/login | E5: Valid credentials login | F5: Active user logs in with correct email/password and receives a JWT + user object. | G5: An active team member exists (e.g. admin seeded via bootstrap_admin). | H5: email=admin@example.com, password=<valid 12+ char> | I5: 1. POST /auth/login with JSON {email,password}. 2. Inspect response body. 3. Decode access_token. | J5: 200 with {access_token, token_type:'bearer', user:{id,name,email,role}}; password_hash NOT present; token decodes with sub/email/name/role/exp. | L5: 200 | N5: P0 | O5: Positive | P5: API | Q5: Not Run | T5: Automated | U5: api/routers/requests.py:login -> backend/app/main.py:login
A6: AUTH-TC-002 | B6: Authentication | C6: Login | D6: POST /auth/login | E6: Wrong password | F6: Login attempt with a valid email but incorrect password is rejected. | G6: Active user exists. | H6: email=admin@example.com, password=WrongPass123! | I6: 1. POST /auth/login with wrong password. 2. Read error. | J6: 401 with detail 'Email or password is incorrect.'; no token issued. | L6: 401 | N6: P0 | O6: Negative | P6: API | Q6: Not Run | T6: Manual | U6: backend/app/main.py:login
A7: AUTH-TC-003 | B7: Authentication | C7: Login | D7: POST /auth/login | E7: Nonexistent email | F7: Login with an email that has no account is rejected with the same generic error. | G7: No account for the email. | H7: email=ghost@example.com, password=whatever123 | I7: 1. POST /auth/login. 2. Read error. | J7: 401 generic 'Email or password is incorrect.' (no user enumeration). | L7: 401 | N7: P1 | O7: Security | P7: API | Q7: Not Run | T7: Manual | U7: backend/app/main.py:login | V7: Generic message prevents account enumeration.
A8: AUTH-TC-004 | B8: Authentication | C8: Login | D8: POST /auth/login | E8: Inactive account | F8: A deactivated account cannot log in even with correct password. | G8: Team member exists with is_active=false. | H8: email=disabled@example.com, password=<correct> | I8: 1. Deactivate account (admin). 2. POST /auth/login with correct password. | J8: 401 'Email or password is incorrect.' | L8: 401 | N8: P1 | O8: Business Logic | P8: API | Q8: Not Run | T8: Manual | U8: backend/app/main.py:login (not member.is_active)
A9: AUTH-TC-005 | B9: Authentication | C9: Login | D9: POST /auth/login | E9: Missing password field | F9: Login payload missing password fails schema validation. | G9: - | H9: email=admin@example.com (no password) | I9: 1. POST /auth/login with only email. | J9: 422 Unprocessable Entity (LoginRequest requires password). | L9: 422 | N9: P2 | O9: Negative | P9: API | Q9: Not Run | T9: Manual | U9: api/schemas/team_members.py:LoginRequest | V9: Validated at public API tier.
A10: AUTH-TC-006 | B10: Authentication | C10: Login | D10: POST /auth/login | E10: Malformed email | F10: Login with an invalid email format fails validation. | G10: - | H10: email=not-an-email, password=abc12345 | I10: 1. POST /auth/login with malformed email. | J10: 422 (EmailStr validation). | L10: 422 | N10: P2 | O10: Negative | P10: API | Q10: Not Run | T10: Manual | U10: api/schemas/team_members.py:LoginRequest
A11: AUTH-TC-007 | B11: Authentication | C11: JWT | D11: GET /requests | E11: Missing Authorization header | F11: Protected endpoint called without a token is rejected. | G11: - | H11: No Authorization header. | I11: 1. GET /requests with no Authorization header. | J11: 401 'Sign-in required.' with WWW-Authenticate: Bearer. | L11: 401 | N11: P0 | O11: Authentication | P11: API | Q11: Not Run | T11: Automated | U11: api/auth.py:get_current_user (credentials is None)
A12: AUTH-TC-008 | B12: Authentication | C12: JWT | D12: GET /requests | E12: Malformed/invalid token | F12: A garbage bearer token is rejected. | G12: - | H12: Authorization: Bearer not.a.jwt | I12: 1. GET /requests with invalid token. | J12: 401 'Invalid or expired sign-in token.' | L12: 401 | N12: P0 | O12: Authentication | P12: API | Q12: Not Run | T12: Manual | U12: api/auth.py:get_current_user (jwt.InvalidTokenError)
A13: AUTH-TC-009 | B13: Authentication | C13: JWT | D13: GET /requests (backend) | E13: Expired token | F13: A JWT past its exp is rejected. | G13: Ability to craft a token with past exp using the test secret. | H13: JWT with exp in the past. | I13: 1. Craft expired JWT. 2. Call a protected endpoint. | J13: 401 invalid/expired token. | L13: 401 | N13: P1 | O13: Authentication | P13: API | Q13: Not Run | T13: Manual | U13: backend/app/auth.py:get_current_user | V13: Token lifetime = 8h.
A14: AUTH-TC-010 | B14: Authentication | C14: JWT | D14: GET /requests (backend) | E14: Valid signature but user deleted/inactive | F14: Backend re-loads the user; a token for a now-inactive user is rejected. | G14: User existed when token issued, later deactivated. | H14: Previously valid JWT for a now-inactive member. | I14: 1. Issue token. 2. Deactivate user. 3. Call protected backend endpoint. | J14: 401 'Account is inactive or unavailable.' | L14: 401 | N14: P1 | O14: Security | P14: API | Q14: Not Run | T14: Manual | U14: backend/app/auth.py:get_current_user (not member.is_active)
A15: AUTH-TC-011 | B15: Authentication | C15: Login UI | D15: LoginForm.jsx | E15: Role mismatch at login screen | F15: Logging in via the wrong role tab shows a guiding error. | G15: Account with a specific role exists. | H15: support account logging in on the Admin tab. | I15: 1. Choose Admin role. 2. Sign in with a support account. | J15: Client blocks with message to use the correct role option; no session established for mismatched role tab. | L15: 200(API)/UI-block | N15: P2 | O15: UI | P15: UI | Q15: Not Run | T15: Manual | U15: frontend/src/components/LoginForm.jsx | V15: API returns 200; UI enforces role-tab match.
A16: AUTH-TC-012 | B16: Authentication | C16: Logout | D16: App.jsx handleLogout | E16: Logout clears session | F16: Logging out removes token and user from localStorage. | G16: Logged-in session. | H16: - | I16: 1. Log in. 2. Click Sign out. 3. Inspect localStorage. | J16: supportDeskToken and supportDeskUser removed; UI returns to welcome. | L16: N/A | N16: P2 | O16: UI | P16: UI | Q16: Not Run | T16: Manual | U16: frontend/src/App.jsx:handleLogout | V16: No server-side token revocation (stateless JWT).
A17: RBAC-TC-001 | B17: Authorization | C17: RBAC | D17: POST /team-members | E17: Employee forbidden from admin action | F17: An employee calling an admin-only endpoint is forbidden. | G17: Employee JWT available. | H17: employee JWT; body {name,email,password,role} | I17: 1. POST /team-members with employee token. | J17: 403 'You do not have permission for this action.' | L17: 403 | N17: P0 | O17: Authorization | P17: API | Q17: Not Run | T17: Manual | U17: backend/app/auth.py:require_roles('admin')
A18: RBAC-TC-002 | B18: Authorization | C18: RBAC | D18: PATCH /requests/{id} | E18: Employee cannot edit tickets | F18: Employee role cannot update ticket fields. | G18: Employee owns a ticket. | H18: employee JWT; body {priority:'High'} | I18: 1. PATCH /requests/{own_id} with employee token. | J18: 403 permission denied. | L18: 403 | N18: P0 | O18: Authorization | P18: API | Q18: Not Run | T18: Manual | U18: api/routers/requests.py:update_ticket require_roles('support','admin')
A19: RBAC-TC-003 | B19: Authorization | C19: RBAC | D19: GET /dashboard/summary | E19: Employee cannot view dashboard | F19: Dashboard is support/admin only. | G19: Employee JWT. | H19: employee JWT | I19: 1. GET /dashboard/summary with employee token. | J19: 403 permission denied. | L19: 403 | N19: P1 | O19: Authorization | P19: API | Q19: Not Run | T19: Manual | U19: api/routers/requests.py:dashboard require_roles('support','admin')
A20: RBAC-TC-004 | B20: Authorization | C20: RBAC | D20: GET /access-requests | E20: Support cannot review access requests | F20: Access request management is admin only. | G20: Support JWT. | H20: support JWT | I20: 1. GET /access-requests with support token. | J20: 403 permission denied. | L20: 403 | N20: P1 | O20: Authorization | P20: API | Q20: Not Run | T20: Manual | U20: backend/app/main.py:list_access_requests require_roles('admin')
A21: RBAC-TC-005 | B21: Authorization | C21: Ownership | D21: GET /requests/{id} | E21: Employee cannot read another user's ticket | F21: Cross-user ticket access returns 404 (existence hidden). | G21: Two employees; ticket owned by employee B. | H21: employee A JWT; id of B's ticket | I21: 1. GET /requests/{B_ticket} as employee A. | J21: 404 'Request {id} not found.' (not 403). | L21: 404 | N21: P0 | O21: Security | P21: API | Q21: Not Run | T21: Automated | U21: backend/app/main.py:get_internal_request ownership check
A22: RBAC-TC-006 | B22: Authorization | C22: Ownership | D22: GET /requests | E22: Employee list scoped to own tickets | F22: Employee listing returns only their own tickets. | G22: Multiple tickets by different requesters. | H22: employee JWT | I22: 1. GET /requests as employee. | J22: 200 with only tickets where requester_email == employee email. | L22: 200 | N22: P0 | O22: Security | P22: API | Q22: Not Run | T22: Automated | U22: backend/app/main.py:list_internal_requests (requester_email filter)
A23: RBAC-TC-007 | B23: Authorization | C23: Privilege escalation | D23: PATCH /team-members/{id} | E23: Admin cannot self-demote/deactivate | F23: An admin editing their own account to remove admin or deactivate is blocked. | G23: Logged-in admin. | H23: admin JWT; body {is_active:false} on own id | I23: 1. PATCH /team-members/{own_id} is_active=false. | J23: 400 'You cannot deactivate or demote your own account.' | L23: 400 | N23: P1 | O23: Business Logic | P23: API | Q23: Not Run | T23: Automated | U23: backend/app/main.py:update_team_member self-guard
A24: RBAC-TC-008 | B24: Authorization | C24: Business rule | D24: PATCH /team-members/{id} | E24: Last active admin protection | F24: Demoting/deactivating the only remaining active admin is blocked. | G24: Exactly one active admin. | H24: admin JWT; demote the only admin | I24: 1. Ensure single active admin. 2. PATCH to role=support. | J24: 400 'At least one active administrator must remain.' | L24: 400 | N24: P1 | O24: Business Logic | P24: API | Q24: Not Run | T24: Manual | U24: backend/app/services/request_service.py:update_team_member count_active_admins
A25: RBAC-TC-009 | B25: Authorization | C25: RBAC matrix | D25: POST /requests | E25: All three roles may create tickets | F25: employee, support, admin can each create a ticket. | G25: One JWT per role. | H25: valid ticket payload per role | I25: 1. POST /requests with each role token. | J25: 201 for all three roles (employee restricted to own email). | L25: 201 | N25: P1 | O25: Authorization | P25: API | Q25: Not Run | T25: Manual | U25: backend/app/main.py:create_internal_request require_roles('employee','support','admin')
A26: RBAC-TC-010 | B26: Authorization | C26: RBAC | D26: POST /requests/{id}/chat/close | E26: Employee cannot close chat | F26: Closing/reopening a chat is support/admin only. | G26: Open conversation on employee's own ticket. | H26: employee JWT | I26: 1. POST /requests/{own}/chat/close as employee. | J26: 403 'Only support staff can close a chat.' | L26: 403 | N26: P2 | O26: Authorization | P26: API | Q26: Not Run | T26: Automated | U26: backend/app/services/chat_service.py:close_conversation
A27: REQ-TC-001 | B27: Request Lifecycle | C27: Create ticket | D27: POST /requests | E27: Create ticket success | F27: Valid payload creates a ticket with status Open and server timestamps. | G27: Authenticated user. | H27: {title,description,requester_name,requester_email,category:'Infrastructure'} | I27: 1. POST /requests with valid body. 2. Inspect response. 3. Verify row in support_requests. | J27: 201 with ticket id, status 'Open', created_at/updated_at set; history 'created' event written. | L27: 201 | N27: P0 | O27: Positive | P27: API | Q27: Not Run | T27: Automated | U27: api/routers/requests.py:create_ticket -> backend create_internal_request
A28: REQ-TC-002 | B28: Request Lifecycle | C28: Create ticket | D28: POST /requests | E28: Missing title | F28: Create without title fails schema validation at the public API. | G28: Authenticated user. | H28: payload without title | I28: 1. POST /requests without title. | J28: 422 (TicketCreate.title min_length=1 required). | L28: 422 | N28: P1 | O28: Negative | P28: API | Q28: Not Run | T28: Automated | U28: api/schemas/request.py:TicketCreate
... A41: REQ-TC-015 | B41: Request Lifecycle | C41: Update ticket | D41: PATCH /requests/{id} | E41: Update editable fields | F41: Support updates priority/due_date. | G41: Ticket exists. | H41: {priority:'High', due_date:'2026-12-01'} | I41: 1. PATCH /requests/{id} as support. | J41: 200 updated ticket reflecting new values. | L41: 200 | N41: P1 | O41: Positive | P41: API | Q41: Not Run | T41: Manual | U41: backend/app/main.py:update_internal_request; service.update_request
A42: REQ-TC-016 | B42: Request Lifecycle | C42: Update ticket | D42: PATCH /requests/{id} | E42: Unsupported field rejected | F42: Updating a non-editable field is forbidden by schema (extra=forbid). | G42: Ticket exists. | H42: {status:'Resolved'} via PATCH /requests/{id} | I42: 1. PATCH with a disallowed field. | J42: 422 (TicketUpdate extra=forbid) at public API. | L42: 422 | N42: P2 | O42: Negative | P42: API | Q42: Not Run | T42: Manual | U42: api/schemas/request.py:TicketUpdate extra=forbid | V42: Status change has its own endpoint.
A43: REQ-TC-017 | B43: Request Lifecycle | C43: Assignment | D43: PATCH /requests/{id}/assignment | E43: Assign ticket to active member | F43: Support assigns a ticket to an active team member. | G43: Ticket + active member exist. | H43: {assigned_to: <member_id>} | I43: 1. PATCH assignment. 2. Check history + assigned_to_name. | J43: 200; assigned_to set; history 'assignment' event recorded. | L43: 200 | N43: P1 | O43: Positive | P43: API | Q43: Not Run | T43: Manual | U43: backend/app/main.py:assign_internal_request; service.assign_request
A44: REQ-TC-018 | B44: Request Lifecycle | C44: Assignment | D44: PATCH /requests/{id}/assignment | E44: Assign to inactive member | F44: Assigning to an inactive member is rejected. | G44: Inactive member exists. | H44: {assigned_to: <inactive_id>} | I44: 1. PATCH assignment to inactive member. | J44: 400 'Cannot assign a request to an inactive team member.' | L44: 400 | N44: P2 | O44: Business Logic | P44: API | Q44: Not Run | T44: Manual | U44: request_service.py:assign_request
A45: REQ-TC-019 | B45: Request Lifecycle | C45: Assignment | D45: PATCH /requests/{id}/assignment | E45: Unassign ticket | F45: Setting assigned_to=null unassigns the ticket. | G45: Assigned ticket. | H45: {assigned_to: null} | I45: 1. PATCH assignment assigned_to=null. | J45: 200; assigned_to null; history 'Request unassigned'. | L45: 200 | N45: P2 | O45: Positive | P45: API | Q45: Not Run | T45: Manual | U45: backend/app/main.py:assign_internal_request
A46: REQ-TC-020 | B46: Request Lifecycle | C46: Status | D46: PATCH /requests/{id}/status | E46: Valid transition Open->In Progress | F46: An allowed status transition succeeds. | G46: Ticket in Open. | H46: {status:'In Progress'} | I46: 1. PATCH status to In Progress. | J46: 200; status updated; history 'status_change' recorded. | L46: 200 | N46: P1 | O46: Positive | P46: API | Q46: Not Run | T46: Automated | U46: backend/app/services/status_service.py:validate_status_transition
A47: REQ-TC-021 | B47: Request Lifecycle | C47: Status | D47: PATCH /requests/{id}/status | E47: Invalid transition Open->Resolved | F47: A disallowed transition is rejected. | G47: Ticket in Open. | H47: {status:'Resolved'} | I47: 1. PATCH status Open->Resolved. | J47: 400 'Cannot transition status from Open to Resolved.' | L47: 400 | N47: P1 | O47: Business Logic | P47: API | Q47: Not Run | T47: Automated | U47: status_service.py VALID_TRANSITIONS
A48: REQ-TC-022 | B48: Request Lifecycle | C48: Status | D48: PATCH /requests/{id}/status | E48: Unknown status value | F48: An invalid status string is rejected. | G48: Ticket exists. | H48: {status:'Archived'} | I48: 1. PATCH status to Archived. | J48: 422 (StatusUpdate enum) at public API / 400 at backend. | L48: 422/400 | N48: P2 | O48: Negative | P48: API | Q48: Not Run | T48: Manual | U48: api/schemas/status.py:RequestStatus
A49: REQ-TC-023 | B49: Request Lifecycle | C49: Notes | D49: POST /requests/{id}/notes | E49: Add internal note | F49: Support adds a private note (is_public=false). | G49: Ticket exists. | H49: {note:'Investigating', created_by:'Agent', is_public:false} | I49: 1. POST note. 2. GET history. | J49: 201 note; history 'Internal note added'. | L49: 201 | N49: P1 | O49: Positive | P49: API | Q49: Not Run | T49: Manual | U49: backend/app/main.py:add_request_note; history_service.add_note
A50: REQ-TC-024 | B50: Request Lifecycle | C50: Notes | D50: POST /requests/{id}/notes | E50: Add public progress update | F50: A public note is visible to the requester. | G50: Ticket exists. | H50: {note:'Fix in progress', is_public:true} | I50: 1. POST public note. 2. As owning employee GET /requests/{id}/notes. | J50: 201; employee sees this note (public only). | L50: 201 | N50: P1 | O50: Business Logic | P50: API | Q50: Not Run | T50: Manual | U50: backend/app/main.py:get_request_notes public filter
A51: REQ-TC-025 | B51: Request Lifecycle | C51: Notes | D51: POST /requests/{id}/notes | E51: Empty note rejected | F51: A blank note is rejected. | G51: Ticket exists. | H51: {note:'', created_by:'Agent'} | I51: 1. POST empty note. | J51: 422 (NoteCreate min_length=1) / 400 at backend. | L51: 422/400 | N51: P2 | O51: Negative | P51: API | Q51: Not Run | T51: Manual | U51: api/schemas/note.py:NoteCreate
A52: REQ-TC-026 | B52: Request Lifecycle | C52: History | D52: GET /requests/{id}/history | E52: History reflects lifecycle events | F52: History lists created/assignment/status/note events in order. | G52: Ticket with several actions. | H52: valid id | I52: 1. Create, assign, change status, add note. 2. GET history. | J52: 200 ordered events (created, assignment, status_change, note). | L52: 200 | N52: P1 | O52: Integration | P52: API | Q52: Not Run | T52: Manual | U52: backend/app/main.py:get_request_history; history_service.list
A53: REQ-TC-027 | B53: Request Lifecycle | C53: Progress updates | D53: GET /progress-updates | E53: Employee sees own public updates | F53: Employee retrieves public notes across their own tickets. | G53: Employee has tickets with public notes. | H53: employee JWT | I53: 1. GET /progress-updates as employee. | J53: 200 list of public notes for the employee's tickets with ticket_title. | L53: 200 | N53: P1 | O53: Positive | P53: API | Q53: Not Run | T53: Automated | U53: backend/app/main.py:get_employee_progress_updates
...

Sheet API Test Cases
A1: API Endpoint Inventory (Public API :4000 → Internal Backend :8001)
A3: Method | B3: Public Endpoint | C3: Internal Backend Endpoint | D3: Auth | E3: Allowed Roles | F3: Notes / Rules | G3: Related Test Case IDs
A4: POST | B4: /auth/login | C4: /internal/auth/login | D4: None | E4: - | F4: Issues JWT; backend verifies password + is_active | G4: AUTH-TC-001, AUTH-TC-002, AUTH-TC-003, AUTH-TC-004, AUTH-TC-005, AUTH-TC-006
A5: POST | B5: /auth/forgot-password | C5: /internal/auth/forgot-password | D5: None | E5: - | F5: Always 200; emails token if active user + SMTP configured | G5: PWD-TC-001
A6: POST | B6: /auth/reset-password | C6: /internal/auth/reset-password | D6: None | E6: - | F6: Validates hashed, unexpired, single-use token | G6: PWD-TC-002, PWD-TC-003
A7: POST | B7: /auth/signup | C7: /internal/access-requests | D7: None | E7: - | F7: Creates pending AccessRequest (role employee|support) | G7: ACC-TC-001, ACC-TC-002, ACC-TC-003
A8: POST | B8: /requests | C8: /internal/requests | D8: JWT | E8: employee, support, admin | F8: Employee can only use own email | G8: AUTH-TC-007, AUTH-TC-008, AUTH-TC-009, AUTH-TC-010, RBAC-TC-002, RBAC-TC-005, RBAC-TC-006, RBAC-TC-009
A9: GET | B9: /requests | C9: /internal/requests | D9: JWT | E9: employee(own), support, admin | F9: Employee list filtered to own email | G9: AUTH-TC-007, AUTH-TC-008, AUTH-TC-009, AUTH-TC-010, RBAC-TC-002, RBAC-TC-005, RBAC-TC-006, RBAC-TC-009
A10: GET | B10: /requests/{id} | C10: /internal/requests/{id} | D10: JWT | E10: employee(own), support, admin | F10: Employee non-owner -> 404 | G10: AUTH-TC-007, AUTH-TC-008, AUTH-TC-009, AUTH-TC-010, RBAC-TC-002, RBAC-TC-005, RBAC-TC-006, RBAC-TC-009
A11: PATCH | B11: /requests/{id} | C11: /internal/requests/{id} | D11: JWT | E11: support, admin | F11: Edit title/description/priority/etc | G11: AUTH-TC-007, AUTH-TC-008, AUTH-TC-009, AUTH-TC-010, RBAC-TC-002, RBAC-TC-005, RBAC-TC-006, RBAC-TC-009
A12: PATCH | B12: /requests/{id}/assignment | C12: /internal/requests/{id}/assignment | D12: JWT | E12: support, admin | F12: Assign/unassign; writes history | G12: AUTH-TC-007, AUTH-TC-008, AUTH-TC-009, AUTH-TC-010, RBAC-TC-002, RBAC-TC-005, RBAC-TC-006, RBAC-TC-009
A13: PATCH | B13: /requests/{id}/status | C13: /internal/requests/{id}/status | D13: JWT | E13: support, admin | F13: Validated state machine; writes history | G13: AUTH-TC-007, AUTH-TC-008, AUTH-TC-009, AUTH-TC-010, RBAC-TC-002, RBAC-TC-005, RBAC-TC-006, RBAC-TC-009
A14: POST | B14: /requests/{id}/notes | C14: /internal/requests/{id}/notes | D14: JWT | E14: support, admin | F14: is_public shares with requester; writes history | G14: AUTH-TC-007, AUTH-TC-008, AUTH-TC-009, AUTH-TC-010, RBAC-TC-002, RBAC-TC-005, RBAC-TC-006, RBAC-TC-009
... A33: POST | B33: /requests/{id}/chat/reopen | C33: /internal/requests/{id}/chat/reopen | D33: JWT | E33: support, admin | F33: Employee -> 403 | G33: AUTH-TC-007, AUTH-TC-008, AUTH-TC-009, AUTH-TC-010, RBAC-TC-002, RBAC-TC-005, RBAC-TC-006, RBAC-TC-009
A34: WS | B34: ws://localhost:8001/internal/requests/{id}/chat/ws?token=JWT | C34: (backend direct) | D34: JWT (query param) | E34: employee(own), support, admin | F34: Not proxied; browser connects to backend
A35: GET | B35: /health | C35: /health | D35: None | E35: - | F35: Liveness for both tiers | G35: INFRA-TC-001, INFRA-TC-002

Sheet Authentication and RBAC
A1: Authentication & RBAC — Permission Matrix (from code)
A2: Y = allowed, N = forbidden (403), Own = allowed only for the user's own ticket.
A4: Action / Capability | B4: employee | C4: support | D4: admin
A5: Login / Logout | B5: Y | C5: Y | D5: Y
A6: Create ticket | B6: Own | C6: Y | D6: Y
A7: List tickets | B7: Own | C7: Y | D7: Y
A8: View ticket detail | B8: Own | C8: Y | D8: Y
A9: Edit ticket fields | B9: N | C9: Y | D9: Y
A10: Assign ticket | B10: N | C10: Y | D10: Y
A11: Change status | B11: N | C11: Y | D11: Y
A12: Add note (internal/public) | B12: N | C12: Y | D12: Y
A13: View notes | B13: Own/public-only | C13: Y | D13: Y
A14: View history | B14: N | C14: Y | D14: Y
A15: Progress updates feed | B15: Y (own) | C15: N | D15: N
... A24: Review access requests | B24: N | C24: N | D24: Y
A26: Authentication / JWT facts (verified)
A27: Fact | B27: Source | C27: Detail
A28: AUTH_SECRET_KEY | B28: api/auth.py, backend/app/auth.py | C28: JWT HS256 signing secret (shared by both tiers)
A29: JWT algorithm | B29: backend/app/auth.py | C29: HS256
A30: Token lifetime | B30: backend/app/auth.py | C30: 8 hours (TOKEN_LIFETIME = timedelta(hours=8))
A31: JWT claims | B31: backend/app/auth.py create_access_token | C31: sub, email, name, role, iat, exp
A32: Password hashing | B32: backend/app/auth.py | C32: pwdlib PasswordHash.recommended() (argon2)
A33: Password min (team-member create/update) | B33: backend/app/main.py | C33: 12 chars
A34: Password min (signup/reset) | B34: backend/app/main.py | C34: 6 chars
A36: Authentication / Authorization / Password Test Cases
A37: Test Case ID | B37: Scenario | C37: Endpoint | D37: Expected Result | E37: HTTP Exp | F37: Priority | G37: Execution Status | H37: Source
A38: AUTH-TC-001 | B38: Valid credentials login | C38: POST /auth/login | D38: 200 with {access_token, token_type:'bearer', user:{id,name,email,role}}; password_hash NOT present; token decodes with sub/email/name/role/exp. | E38: 200 | F38: P0 | G38: Not Run | H38: api/routers/requests.py:login -> backend/app/main.py:login
A39: AUTH-TC-002 | B39: Wrong password | C39: POST /auth/login | D39: 401 with detail 'Email or password is incorrect.'; no token issued. | E39: 401 | F39: P0 | G39: Not Run | H39: backend/app/main.py:login
A40: AUTH-TC-003 | B40: Nonexistent email | C40: POST /auth/login | D40: 401 generic 'Email or password is incorrect.' (no user enumeration). | E40: 401 | F40: P1 | G40: Not Run | H40: backend/app/main.py:login
A41: AUTH-TC-004 | B41: Inactive account | C41: POST /auth/login | D41: 401 'Email or password is incorrect.' | E41: 401 | F41: P1 | G41: Not Run | H41: backend/app/main.py:login (not member.is_active)
A42: AUTH-TC-005 | B42: Missing password field | C42: POST /auth/login | D42: 422 Unprocessable Entity (LoginRequest requires password). | E42: 422 | F42: P2 | G42: Not Run | H42: api/schemas/team_members.py:LoginRequest
A43: AUTH-TC-006 | B43: Malformed email | C43: POST /auth/login | D43: 422 (EmailStr validation). | E43: 422 | F43: P2 | G43: Not Run | H43: api/schemas/team_members.py:LoginRequest
A44: AUTH-TC-007 | B44: Missing Authorization header | C44: GET /requests | D44: 401 'Sign-in required.' with WWW-Authenticate: Bearer. | E44: 401 | F44: P0 | G44: Not Run | H44: api/auth.py:get_current_user (credentials is None)
A45: AUTH-TC-008 | B45: Malformed/invalid token | C45: GET /requests | D45: 401 'Invalid or expired sign-in token.' | E45: 401 | F45: P0 | G45: Not Run | H45: api/auth.py:get_current_user (jwt.InvalidTokenError)
A46: AUTH-TC-009 | B46: Expired token | C46: GET /requests (backend) | D46: 401 invalid/expired token. | E46: 401 | F46: P1 | G46: Not Run | H46: backend/app/auth.py:get_current_user
A47: AUTH-TC-010 | B47: Valid signature but user deleted/inactive | C47: GET /requests (backend) | D47: 401 'Account is inactive or unavailable.' | E47: 401 | F47: P1 | G47: Not Run | H47: backend/app/auth.py:get_current_user (not member.is_active)
A48: AUTH-TC-011 | B48: Role mismatch at login screen | C48: LoginForm.jsx | D48: Client blocks with message to use the correct role option; no session established for mismatched role tab. | E48: 200(API)/UI-block | F48: P2 | G48: Not Run | H48: frontend/src/components/LoginForm.jsx
... A62: PWD-TC-003 | B62: Short new password rejected | C62: POST /auth/reset-password | D62: 400 (min 6) / 422 at public API schema. | E62: 400/422 | F62: P2 | G62: Not Run | H62: api/schemas/password_reset.py; backend reset_password

Sheet Request Lifecycle
A1: Request Lifecycle
A2: Create, list, get, update, assign, status, notes, history, team & access-request flows.
A4: Test Case ID | B4: Feature | C4: API / Endpoint | D4: Test Scenario | E4: Execution Steps | F4: Expected Result | G4: HTTP Exp | H4: Priority | I4: Test Type | J4: Execution Status | K4: Source File / Function | L4: Remarks
A5: REQ-TC-001 | B5: Create ticket | C5: POST /requests | D5: Create ticket success | E5: 1. POST /requests with valid body. 2. Inspect response. 3. Verify row in support_requests. | F5: 201 with ticket id, status 'Open', created_at/updated_at set; history 'created' event written. | G5: 201 | H5: P0 | I5: Positive | J5: Not Run | K5: api/routers/requests.py:create_ticket -> backend create_internal_request
A6: REQ-TC-002 | B6: Create ticket | C6: POST /requests | D6: Missing title | E6: 1. POST /requests without title. | F6: 422 (TicketCreate.title min_length=1 required). | G6: 422 | H6: P1 | I6: Negative | J6: Not Run | K6: api/schemas/request.py:TicketCreate
A7: REQ-TC-003 | B7: Create ticket | C7: POST /requests | D7: Invalid category enum | E7: 1. POST /requests with bad category. | F7: 422 (Category enum). | G7: 422 | H7: P2 | I7: Negative | J7: Not Run | K7: api/schemas/request.py:Category
A8: REQ-TC-004 | B8: Create ticket | C8: POST /requests | D8: Invalid priority enum | E8: 1. POST /requests with bad priority. | F8: 422 (Priority enum). | G8: 422 | H8: P2 | I8: Negative | J8: Not Run | K8: api/schemas/request.py:Priority
A9: REQ-TC-005 | B9: Create ticket | C9: POST /requests | D9: Invalid requester email | E9: 1. POST /requests with malformed email. | F9: 422 (EmailStr). | G9: 422 | H9: P2 | I9: Negative | J9: Not Run | K9: api/schemas/request.py:TicketCreate
A10: REQ-TC-006 | B10: Create ticket | C10: POST /requests | D10: Title boundary max length | E10: 1. POST with 200-char title -> expect ok. 2. POST with 201-char title -> expect fail. | F10: 200-char: 201 created; 201-char: 422 (max_length=200). | G10: 201 / 422 | H10: P2 | I10: Boundary | J10: Not Run | K10: api/schemas/request.py:TicketCreate title max_length=200
A11: REQ-TC-007 | B11: Create ticket | C11: POST /requests | D11: Description boundary max length | E11: 1. POST with 5000-char description. 2. POST with 5001-char description. | F11: 5000: 201; 5001: 422 (max_length=5000). | G11: 201 / 422 | H11: P2 | I11: Boundary | J11: Not Run | K11: api/schemas/request.py:TicketCreate description max_length=5000
A12: REQ-TC-008 | B12: Create ticket | C12: POST /requests | D12: Employee creating for another email | E12: 1. POST /requests as employee with another email. | F12: 403 'Employees can only submit tickets for their own account.' | G12: 403 | H12: P0 | I12: Security | J12: Not Run | K12: api/routers/requests.py:create_ticket + backend check
A13: REQ-TC-009 | B13: Create ticket | C13: POST /requests | D13: Default priority applied | E13: 1. POST /requests without priority. 2. Inspect stored priority. | F13: 201; priority == 'Medium'. | G13: 201 | H13: P2 | I13: Business Logic | J13: Not Run | K13: api/schemas/request.py:Priority default Medium
A14: REQ-TC-010 | B14: List tickets | C14: GET /requests | D14: List with filters and sort | E14: 1. GET /requests with filters as support. | F14: 200 list honoring filters and sort order. | G14: 200 | H14: P1 | I14: Positive | J14: Not Run | K14: api/routers/requests.py:list_requests; repo.list_requests
A15: REQ-TC-011 | B15: List tickets | C15: GET /requests | D15: Invalid sort field | E15: 1. GET /requests?sort_by=unknown. | F15: 400 'Invalid sort field.' | G15: 400 | H15: P2 | I15: Negative | J15: Not Run | K15: api/routers/requests.py:list_requests VALID_SORT_BY
A16: REQ-TC-012 | B16: Get ticket | C16: GET /requests/{id} | D16: Get existing ticket | E16: 1. GET /requests/{id} as support. | F16: 200 with full ticket dict incl assigned_to_name. | G16: 200 | H16: P1 | I16: Positive | J16: Not Run | K16: backend/app/main.py:get_internal_request
... A19: REQ-TC-015 | B19: Update ticket | C19: PATCH /requests/{id} | D19: Update editable fields | E19: 1. PATCH /requests/{id} as support. | F19: 200 updated ticket reflecting new values. | G19: 200 | H19: P1 | I19: Positive | J19: Not Run | K19: backend/app/main.py:update_internal_request; service.update_request
A20: REQ-TC-016 | B20: Update ticket | C20: PATCH /requests/{id} | D20: Unsupported field rejected | E20: 1. PATCH with a disallowed field. | F20: 422 (TicketUpdate extra=forbid) at public API. | G20: 422 | H20: P2 | I20: Negative | J20: Not Run | K20: api/schemas/request.py:TicketUpdate extra=forbid | L20: Status change has its own endpoint.
A21: REQ-TC-017 | B21: Assignment | C21: PATCH /requests/{id}/assignment | D21: Assign ticket to active member | E21: 1. PATCH assignment. 2. Check history + assigned_to_name. | F21: 200; assigned_to set; history 'assignment' event recorded. | G21: 200 | H21: P1 | I21: Positive | J21: Not Run | K21: backend/app/main.py:assign_internal_request; service.assign_request
A22: REQ-TC-018 | B22: Assignment | C22: PATCH /requests/{id}/assignment | D22: Assign to inactive member | E22: 1. PATCH assignment to inactive member. | F22: 400 'Cannot assign a request to an inactive team member.' | G22: 400 | H22: P2 | I22: Business Logic | J22: Not Run | K22: request_service.py:assign_request
A23: REQ-TC-019 | B23: Assignment | C23: PATCH /requests/{id}/assignment | D23: Unassign ticket | E23: 1. PATCH assignment assigned_to=null. | F23: 200; assigned_to null; history 'Request unassigned'. | G23: 200 | H23: P2 | I23: Positive | J23: Not Run | K23: backend/app/main.py:assign_internal_request
A24: REQ-TC-020 | B24: Status | C24: PATCH /requests/{id}/status | D24: Valid transition Open->In Progress | E24: 1. PATCH status to In Progress. | F24: 200; status updated; history 'status_change' recorded. | G24: 200 | H24: P1 | I24: Positive | J24: Not Run | K24: backend/app/services/status_service.py:validate_status_transition
A25: REQ-TC-021 | B25: Status | C25: PATCH /requests/{id}/status | D25: Invalid transition Open->Resolved | E25: 1. PATCH status Open->Resolved. | F25: 400 'Cannot transition status from Open to Resolved.' | G25: 400 | H25: P1 | I25: Business Logic | J25: Not Run | K25: status_service.py VALID_TRANSITIONS
A26: REQ-TC-022 | B26: Status | C26: PATCH /requests/{id}/status | D26: Unknown status value | E26: 1. PATCH status to Archived. | F26: 422 (StatusUpdate enum) at public API / 400 at backend. | G26: 422/400 | H26: P2 | I26: Negative | J26: Not Run | K26: api/schemas/status.py:RequestStatus
A27: REQ-TC-023 | B27: Notes | C27: POST /requests/{id}/notes | D27: Add internal note | E27: 1. POST note. 2. GET history. | F27: 201 note; history 'Internal note added'. | G27: 201 | H27: P1 | I27: Positive | J27: Not Run | K27: backend/app/main.py:add_request_note; history_service.add_note
A28: REQ-TC-024 | B28: Notes | C28: POST /requests/{id}/notes | D28: Add public progress update | E28: 1. POST public note. 2. As owning employee GET /requests/{id}/notes. | F28: 201; employee sees this note (public only). | G28: 201 | H28: P1 | I28: Business Logic | J28: Not Run | K28: backend/app/main.py:get_request_notes public filter
A29: REQ-TC-025 | B29: Notes | C29: POST /requests/{id}/notes | D29: Empty note rejected | E29: 1. POST empty note. | F29: 422 (NoteCreate min_length=1) / 400 at backend. | G29: 422/400 | H29: P2 | I29: Negative | J29: Not Run | K29: api/schemas/note.py:NoteCreate
A30: REQ-TC-026 | B30: History | C30: GET /requests/{id}/history | D30: History reflects lifecycle events | E30: 1. Create, assign, change status, add note. 2. GET history. | F30: 200 ordered events (created, assignment, status_change, note). | G30: 200 | H30: P1 | I30: Integration | J30: Not Run | K30: backend/app/main.py:get_request_history; history_service.list
A31: REQ-TC-027 | B31: Progress updates | C31: GET /progress-updates | D31: Employee sees own public updates | E31: 1. GET /progress-updates as employee. | F31: 200 list of public notes for the employee's tickets with ticket_title. | G31: 200 | H31: P1 | I31: Positive | J31: Not Run | K31: backend/app/main.py:get_employee_progress_updates
A32: TEAM-TC-001 | B32: Create member | C32: POST /team-members | D32: Admin creates a support member | E32: 1. POST /team-members as admin. 2. Login as new member. | F32: 201 member (no password_hash in response); new member can log in. | G32: 201 | H32: P1 | I32: Positive | J32: Not Run | K32: backend/app/main.py:create_team_member
... A41: ACC-TC-005 | B41: Review | C41: PATCH /access-requests/{id} | D41: Double review blocked | E41: 1. PATCH review on a reviewed request. | F41: 409 'This access request has already been reviewed.' | G41: 409 | H41: P2 | I41: Negative | J41: Not Run | K41: backend/app/main.py:review_access_request

Sheet Attachments and MinIO
A1: Attachments and MinIO
A2: Upload/download/delete, validation, size/type limits, ownership, and MinIO resilience.
A4: Test Case ID | B4: Feature | C4: API / Endpoint | D4: Test Scenario | E4: Execution Steps | F4: Expected Result | G4: HTTP Exp | H4: Priority | I4: Test Type | J4: Execution Status | K4: Source File / Function | L4: Remarks
A5: ATT-TC-001 | B5: Upload | C5: POST /requests/{id}/attachments | D5: Upload valid PNG | E5: 1. POST file. 2. GET list. 3. Verify object_key in MinIO + row in request_attachments. | F5: 201 metadata (no object_key leaked); object stored under requests/{id}/<uuid>.png. | G5: 201 | H5: P0 | I5: Positive | J5: Not Run | K5: backend/app/services/attachment_service.py:upload
A6: ATT-TC-002 | B6: Upload | C6: POST /requests/{id}/attachments | D6: Unsupported type rejected | E6: 1. POST .exe file. | F6: 415 unsupported type; no object stored. | G6: 415 | H6: P1 | I6: Negative | J6: Not Run | K6: attachment_service.py:validate_file SUPPORTED_FILES
A7: ATT-TC-003 | B7: Upload | C7: POST /requests/{id}/attachments | D7: Empty file rejected | E7: 1. POST empty file. | F7: 400 'Empty files are not allowed.' | G7: 400 | H7: P2 | I7: Boundary | J7: Not Run | K7: attachment_service.py:validate_file
A8: ATT-TC-004 | B8: Upload | C8: POST /requests/{id}/attachments | D8: Oversized file rejected (>5MB) | E8: 1. POST 5MB+1 file. | F8: 413 'Files must be 5 MB or smaller.' | G8: 413 | H8: P1 | I8: Boundary | J8: Not Run | K8: attachment_service.py MAX_ATTACHMENT_SIZE; public API 5MB guard
A9: ATT-TC-005 | B9: Upload | C9: POST /requests/{id}/attachments | D9: Content/extension mismatch (fake image) | E9: 1. POST fake.png. | F9: 400 invalid image (magic-byte/Pillow verify fails). | G9: 400 | H9: P1 | I9: Security | J9: Not Run | K9: attachment_service.py image verify
A10: ATT-TC-006 | B10: Upload | C10: POST /requests/{id}/attachments | D10: Upload to nonexistent request | E10: 1. POST file to /requests/999999/attachments. | F10: 404; no object stored. | G10: 404 | H10: P2 | I10: Negative | J10: Not Run | K10: attachment_service.py:_get_request
A11: ATT-TC-007 | B11: Authorization | C11: POST /requests/{id}/attachments | D11: Employee cannot upload to another's ticket | E11: 1. POST file as employee A to B's ticket. | F11: 404; no object stored. | G11: 404 | H11: P1 | I11: Security | J11: Not Run | K11: attachment_service.py:_get_request ownership
A12: ATT-TC-008 | B12: Download | C12: GET /attachments/{id} | D12: Download existing attachment | E12: 1. GET /attachments/{id}. | F12: 200 with correct content-type and original bytes; Cache-Control private,no-store. | G12: 200 | H12: P1 | I12: Positive | J12: Not Run | K12: api/routers/attachments.py download proxy; backend router
A13: ATT-TC-009 | B13: Download | C13: GET /attachments/{id} | D13: Download nonexistent attachment | E13: 1. GET /attachments/999999. | F13: 404 attachment not found. | G13: 404 | H13: P2 | I13: Negative | J13: Not Run | K13: attachment_service.py:_get_attachment
A14: ATT-TC-010 | B14: Download | C14: GET /attachments/{id} | D14: Cross-user download blocked | E14: 1. GET /attachments/{B_att} as A. | F14: 404 (ownership hidden). | G14: 404 | H14: P1 | I14: Security | J14: Not Run | K14: attachment_service.py:_get_attachment -> _get_request
A15: ATT-TC-011 | B15: Delete | C15: DELETE /attachments/{id} | D15: Delete attachment | E15: 1. DELETE /attachments/{id}. 2. Verify object + row gone. | F15: 204; MinIO object and DB row removed. | G15: 204 | H15: P2 | I15: Positive | J15: Not Run | K15: attachment_service.py:delete
A16: ATT-TC-012 | B16: Resilience | C16: POST /requests/{id}/attachments | D16: MinIO unavailable | E16: 1. Make MinIO fail ensure_bucket. 2. POST file. | F16: 503 storage unavailable; request_attachments count unchanged. | G16: 503 | H16: P1 | I16: Error Handling | J16: Not Run | K16: attachment_service.py:upload storage try/except
... A18: ATT-TC-014 | B18: Auth | C18: GET /requests/{id}/attachments | D18: Attachment routes require auth | E18: 1. GET /requests/{id}/attachments without auth. | F18: 401 sign-in required. | G18: 401 | H18: P1 | I18: Authentication | J18: Not Run | K18: require_roles chain

Sheet Database and Integration
A1: Database and Integration
A2: Persistence, constraints, migrations, API↔backend integration and error propagation. Do not run destructive deletes against a shared dev DB.
A4: Test Case ID | B4: Feature | C4: API / Endpoint | D4: Test Scenario | E4: Execution Steps | F4: Expected Result | G4: HTTP Exp | H4: Priority | I4: Test Type | J4: Execution Status | K4: Source File / Function | L4: Remarks
A5: DB-TC-001 | B5: Persistence | C5: support_requests | D5: Ticket row persisted | E5: 1. Create ticket. 2. SELECT from support_requests WHERE id=... | F5: Row present with status 'Open', timestamps, requester_email. | G5: N/A | H5: P1 | I5: Database | J5: Not Run | K5: database/app/models.py:SupportRequest; repo.create_request
A6: DB-TC-002 | B6: Cascade | C6: history_events / ticket_notes | D6: Child rows cascade on ticket delete | E6: 1. Inspect FK ondelete + relationship cascade. 2. (Non-destructive) verify config. | F6: history_events/ticket_notes FK CASCADE; relationship cascade all,delete-orphan. | G6: N/A | H6: P2 | I6: Database | J6: Not Run | K6: models.py relationships | L6: No destructive delete run against dev DB.
A7: DB-TC-003 | B7: Unique constraint | C7: team_members.email | D7: Duplicate email constraint | E7: 1. Review unique=True on email. 2. Attempt create via API (TEAM-TC-003). | F7: 409 at API; DB rejects duplicate at constraint level. | G7: 409 | H7: P2 | I7: Database | J7: Not Run | K7: models.py:TeamMember email unique
A8: DB-TC-004 | B8: Unique constraint | C8: chat_conversations.request_id | D8: One conversation per ticket | E8: 1. Open chat twice for one ticket. | F8: Same conversation returned (unique request_id enforced). | G8: 200 | H8: P2 | I8: Database | J8: Not Run | K8: models.py:ChatConversation request_id unique
A9: DB-TC-005 | B9: Migrations | C9: alembic | D9: Migrations upgrade to head | E9: 1. Run alembic upgrade head (or initialize_db). | F9: All revisions apply through latest (chat tables) without error. | G9: N/A | H9: P1 | I9: Integration | J9: Not Run | K9: database/migrations/versions/*; backend/app/initialize_db.py
A10: DB-TC-006 | B10: Service-to-service | C10: Public API -> Backend | D10: Backend unavailable surfaces 502 | E10: 1. Stop backend. 2. Call a public endpoint. | F10: 502 'Backend service is unavailable'. | G10: 502 | H10: P1 | I10: Error Handling | J10: Not Run | K10: api/routers/requests.py:backend_request httpx.RequestError
A11: DB-TC-007 | B11: Error propagation | C11: Public API -> Backend | D11: Backend error detail forwarded | E11: 1. Trigger a backend validation error. 2. Inspect public API response. | F11: Same status code + 'detail' forwarded to client. | G11: 4xx | H11: P2 | I11: Integration | J11: Not Run | K11: api/routers/requests.py:backend_request raise_backend_error

Sheet UI and End-to-End Tests
A1: UI and End-to-End Tests
A2: Frontend forms/validation/states, live chat, health checks, and full user journeys. Only features present in the system.
A4: Test Case ID | B4: Feature | C4: API / Endpoint | D4: Test Scenario | E4: Execution Steps | F4: Expected Result | G4: HTTP Exp | H4: Priority | I4: Test Type | J4: Execution Status | K4: Source File / Function | L4: Remarks
A5: CHAT-TC-001 | B5: Open conversation | C5: POST /requests/{id}/chat | D5: Owner opens chat | E5: 1. POST /requests/{own}/chat. | F5: 200 conversation {status:'open', request_id}. | G5: 200 | H5: P1 | I5: Positive | J5: Not Run | K5: backend/app/services/chat_service.py:get_or_create_conversation
A6: CHAT-TC-002 | B6: Authorization | C6: POST /requests/{id}/chat | D6: Other employee cannot access chat | E6: 1. POST /requests/{B}/chat as A. | F6: 404 request not found. | G6: 404 | H6: P1 | I6: Security | J6: Not Run | K6: chat_service.py:_get_request ownership
A7: CHAT-TC-003 | B7: Messaging (REST) | C7: POST /requests/{id}/chat/messages | D7: Send and persist message | E7: 1. POST message. 2. GET /chat/messages. | F7: 201; message appears in history with sender_role. | G7: 201 | H7: P1 | I7: Positive | J7: Not Run | K7: chat_service.py:add_message
A8: CHAT-TC-004 | B8: Validation | C8: POST /requests/{id}/chat/messages | D8: Empty message rejected | E8: 1. POST empty message. | F8: 400 'A message must contain text or an attachment.' | G8: 400 | H8: P2 | I8: Negative | J8: Not Run | K8: chat_service.py:validate_message
A9: CHAT-TC-005 | B9: Validation | C9: POST /requests/{id}/chat/messages | D9: Oversized message rejected (>4000) | E9: 1. POST 4001-char message. | F9: 400 'Messages must be 4000 characters or fewer.' | G9: 400 | H9: P2 | I9: Boundary | J9: Not Run | K9: chat_service.py MAX_MESSAGE_LENGTH
A10: CHAT-TC-006 | B10: Closed state | C10: POST /requests/{id}/chat/messages | D10: Cannot message a closed chat | E10: 1. Close chat (support). 2. POST message. | F10: 409 'This chat is closed.' | G10: 409 | H10: P2 | I10: Business Logic | J10: Not Run | K10: chat_service.py:add_message closed guard
A11: CHAT-TC-007 | B11: WebSocket auth | C11: WS /internal/requests/{id}/chat/ws | D11: WS rejects missing/invalid token | E11: 1. Connect WS without token. 2. Connect WS with invalid token. | F11: Connection closed with policy-violation (1008); no messages exchanged. | G11: WS 1008 | H11: P1 | I11: Authentication | J11: Not Run | K11: backend/app/ws_auth.py; routers/chat.py:chat_socket
A12: CHAT-TC-008 | B12: WebSocket messaging | C12: WS /internal/requests/{id}/chat/ws | D12: Real-time broadcast to both participants | E12: 1. Connect employee + support WS. 2. Employee sends message. 3. Observe both receive it. | F12: Both sockets receive type:'message'; one row persisted in chat_messages. | G12: WS msg | H12: P1 | I12: Integration | J12: Not Run | K12: backend/app/routers/chat.py; connection_manager.py
A13: CHAT-TC-009 | B13: Reconnect | C13: useChatSocket.js | D13: Client reconnects after drop | E13: 1. Open chat. 2. Drop the connection. 3. Observe reconnect attempts. | F13: Status shows Reconnecting then Connected; history reloads intact. | G13: N/A | H13: P2 | I13: UI | J13: Not Run | K13: frontend/src/useChatSocket.js scheduleReconnect | L13: Backoff 1s->15s cap.
A14: CHAT-TC-010 | B14: Attachment in chat | C14: POST /requests/{id}/chat/messages | D14: Share attachment reuses MinIO pipeline | E14: 1. Upload file via attachments API. 2. Send chat message with attachment_id. | F14: 201 message with attachment_id; download works via /attachments/{id}. | G14: 201 | H14: P2 | I14: Integration | J14: Not Run | K14: ChatPanel.jsx handleAttachment; chat_service.add_message _validate_attachment
A15: UI-TC-001 | B15: Create ticket form | C15: CreateTicketForm.jsx | D15: Required field validation | E15: 1. Open create form. 2. Submit empty. | F15: Browser required-field validation prevents submit; no API call for empty required fields. | G15: N/A | H15: P2 | I15: UI | J15: Not Run | K15: frontend/src/components/CreateTicketForm.jsx
A16: UI-TC-002 | B16: Create ticket form | C16: CreateTicketForm.jsx | D16: Employee fields prefilled read-only | E16: 1. Open create form as employee. | F16: requester_name/email prefilled from session and read-only. | G16: N/A | H16: P2 | I16: UI | J16: Not Run | K16: CreateTicketForm.jsx isEmployee
A17: UI-TC-003 | B17: Attachment picker | C17: CreateTicketForm.jsx | D17: Client-side file validation | E17: 1. Select an unsupported or oversized file. | F17: Inline file error; file not added to selection. | G17: N/A | H17: P2 | I17: UI | J17: Not Run | K17: CreateTicketForm.jsx validateSelectedFile
A18: UI-TC-004 | B18: Login UI | C18: LoginForm.jsx | D18: Error message on failed login | E18: 1. Submit wrong credentials. | F18: Error box 'Unable to sign in' with backend detail. | G18: N/A | H18: P2 | I18: UI | J18: Not Run | K18: LoginForm.jsx error state
A19: UI-TC-005 | B19: Ticket detail chat | C19: TicketDetail.jsx + ChatPanel.jsx | D19: Open live chat from ticket | E19: 1. Open ticket detail. 2. Click Open Live Chat. | F19: Chat panel renders header, history, connection status, composer. | G19: N/A | H19: P2 | I19: UI | J19: Not Run | K19: TicketDetail.jsx showChat; ChatPanel.jsx
A20: E2E-TC-001 | B20: Employee journey | C20: Multiple | D20: Employee creates ticket and tracks progress | E20: 1. Login as employee. 2. Create ticket + attachment. 3. Support adds public note. 4. Employee views progress-updates. | F20: Ticket created; attachment stored; employee sees the public update. | G20: N/A | H20: P1 | I20: E2E | J20: Not Run | K20: frontend + api + backend + MinIO
A21: E2E-TC-002 | B21: Support journey | C21: Multiple | D21: Support resolves a ticket | E21: 1. Login support. 2. Assign. 3. Open->In Progress->Resolved. 4. Add notes. | F21: Status transitions valid; history records each step. | G21: N/A | H21: P1 | I21: E2E | J21: Not Run | K21: backend request/status/history services
A22: E2E-TC-003 | B22: Admin journey | C22: Multiple | D22: Admin approves access and provisions staff | E22: 1. Login admin. 2. Approve access request. 3. New user logs in. | F22: Member created; login works; access request marked approved. | G22: N/A | H22: P1 | I22: E2E | J22: Not Run | K22: access request + team member + auth
A23: E2E-TC-004 | B23: Password reset | C23: Multiple | D23: Forgot/reset password end-to-end | E23: 1. POST /auth/forgot-password. 2. Capture token (mailpit). 3. POST /auth/reset-password. 4. Login with new password. | F23: Reset succeeds; token single-use; login with new password works. | G23: 200 | H23: P1 | I23: E2E | J23: Not Run | K23: backend forgot/reset endpoints; password_reset_tokens
A24: E2E-TC-005 | B24: Live chat | C24: Multiple | D24: Employee-agent live conversation | E24: 1. Employee opens chat. 2. Agent opens same ticket chat. 3. Exchange messages. 4. Agent closes chat. | F24: Messages delivered in real time and persisted; closed chat blocks new messages. | G24: N/A | H24: P1 | I24: E2E | J24: Not Run | K24: chat router + connection_manager + ChatPanel
A25: INFRA-TC-001 | B25: Health | C25: GET /health | D25: Public API health | E25: 1. GET http://localhost:4000/health. | F25: 200 {status:'ok', service:'cloudnaut-support-desk-api'}. | G25: 200 | H25: P2 | I25: Positive | J25: Not Run | K25: api/app.py:health_check
... A27: INFRA-TC-003 | B27: CORS | C27: Public API | D27: CORS allows frontend origins | E27: 1. OPTIONS/GET with allowed Origin header. | F27: CORS headers permit localhost:3000/5173/5174. | G27: 200 | H27: P3 | I27: Integration | J27: Not Run | K27: api/app.py CORSMiddleware

Sheet Test Data and Environment
A1: Test Data & Environment
A2: Use throwaway accounts only. Never enter real passwords, production secrets, or real user data.
A4: Suggested Test Accounts (create via bootstrap_admin + admin UI)
A5: Role | B5: Example Email | C5: Password Rule | D5: How to create
A6: admin | B6: admin@test.local | C6: >=12 chars | D6: python -m app.bootstrap_admin --name Admin --email admin@test.local
A7: support | B7: support@test.local | C7: >=12 chars | D7: Admin creates via POST /team-members
A8: employee | B8: employee@test.local | C8: >=6 chars (signup) | D8: POST /auth/signup then admin approves
A9: employee2 | B9: employee2@test.local | C9: >=6 chars | D9: Second employee for cross-user/ownership tests
A11: Environment Prerequisites
A12: Component | B12: Detail
A13: Startup | B13: docker compose up --build (from repo root)
A14: Frontend | B14: http://localhost:3000
A15: Public API | B15: http://localhost:4000 (health: /health)
A16: Internal backend | B16: http://localhost:8001 (chat WS published; otherwise internal)
A17: PostgreSQL | B17: localhost:5432 db=cloudnaut_db user=cloudnaut
A18: MinIO | B18: bucket support-attachments (console :9001 inside compose)
A19: Mailpit (SMTP) | B19: SMTP :1025, UI http://localhost:8025 for reset emails
A20: Redis | B20: Optional; only for multi-instance chat (REDIS_URL)
A21: .env | B21: Set AUTH_SECRET_KEY, POSTGRES_PASSWORD, MINIO_ROOT_USER/PASSWORD (see .env.example)
A23: Sample Safe Payloads
A24: Purpose | B24: JSON
A25: Login | B25: {"email":"admin@test.local","password":"<local-test-pass>"}
A26: Create ticket | B26: {"title":"Printer offline","description":"3rd floor printer unreachable","requester_name":"Emp One","requester_email":"employee@test.local","category":"Infrastructure","priority":"Medium"}
A27: Change status | B27: {"status":"In Progress"}
A28: Add public note | B28: {"note":"Investigating now","created_by":"Support","is_public":true}
A29: Chat message | B29: {"body":"Hello, any update?"}
A30: Signup | B30: {"name":"Emp Two","email":"employee2@test.local","password":"<local-test-pass>","role":"employee"}
A32: Cleanup / Safety
A33: • Run tests against a disposable dev stack, never production.
A34: • Automated backend tests use in-memory SQLite + mocked MinIO; they do not touch the dev DB.
A35: • To reset dev data: docker compose down -v (drops pgdata + minio_data volumes).
A36: • Do not commit real secrets; keep .env out of version control.

Sheet Requirements Traceability
A1: Requirements Traceability — Module/Endpoint → Test Cases
A3: Module | B3: Endpoint / Capability | C3: Source File | D3: Test Case IDs | E3: Coverage
A4: POST /auth/login | B4: Issues JWT; backend verifies password + is_active | C4: backend/app/main.py; api/routers/requests.py | D4: AUTH-TC-001, AUTH-TC-002, AUTH-TC-003, AUTH-TC-004, AUTH-TC-005, AUTH-TC-006 | E4: Covered
A5: POST /auth/forgot-password | B5: Always 200; emails token if active user + SMTP configured | C5: backend/app/main.py; api/routers/requests.py | D5: PWD-TC-001 | E5: Covered
A6: POST /auth/reset-password | B6: Validates hashed, unexpired, single-use token | C6: backend/app/main.py; api/routers/requests.py | D6: PWD-TC-002, PWD-TC-003 | E6: Covered
A7: POST /auth/signup | B7: Creates pending AccessRequest (role employee|support) | C7: backend/app/main.py; api/routers/requests.py | D7: ACC-TC-001, ACC-TC-002, ACC-TC-003 | E7: Covered
A8: POST /requests | B8: Employee can only use own email | C8: api/routers/requests.py; backend/app/main.py; request_service.py; request_repository.py | D8: AUTH-TC-007, AUTH-TC-008, AUTH-TC-009, AUTH-TC-010, RBAC-TC-002, RBAC-TC-005, RBAC-TC-006, RBAC-TC-009, RBAC-TC-010, REQ-TC-001, REQ-TC-002, REQ-TC-003, REQ-TC-004, REQ-TC-005, REQ-TC-006, REQ-TC-007, REQ-TC-008, REQ-TC-009, REQ-TC-010, REQ-TC-011, REQ-TC-012, REQ-TC-013, REQ-TC-014, REQ-TC-015, REQ-TC-016, REQ-TC-017, REQ-TC-018, REQ-TC-019, REQ-TC-020, REQ-TC-021, REQ-TC-022, REQ-TC-023, REQ-TC-024, REQ-TC-025, REQ-TC-026, ATT-TC-001, ATT-TC-002, ATT-TC-003, ATT-TC-004, ATT-TC-005, ATT-TC-006, ATT-TC-007, ATT-TC-012, ATT-TC-013, ATT-TC-014, CHAT-TC-001, CHAT-TC-002, CHAT-TC-003, CHAT-TC-004, CHAT-TC-005, CHAT-TC-006, CHAT-TC-007, CHAT-TC-008, CHAT-TC-010 | E8: Covered
